# 二十一、异常处理

异常处理允许程序员处理程序中可能出现的意外情况。例如，考虑使用`System.IO`名称空间中的`StreamReader`类打开一个文件。要查看该类可能引发的异常类型，可以将光标悬停在 Visual Studio 中的类名上。例如，你可能会看到`System.IO`例外`FileNotFoundException`和`DirectoryNotFoundException`。如果这些异常中的任何一个发生，程序将终止并显示一条错误消息。

```cs
using System;
using System.IO;

class ErrorHandling
{
  static void Main()
  {
    // Run-time error
    StreamReader sr = new StreamReader("missing.txt");
  }
}

```

## Try-Catch 语句

为了避免程序崩溃，必须使用`try-catch`语句捕捉异常。该语句由一个包含可能导致异常的代码的`try`块和一个或多个`catch`子句组成。如果`try`块成功执行，程序将在`try-catch`语句后继续运行。然而，如果出现异常，执行将被传递到能够处理该异常类型的第一个`catch`模块。

```cs
try {
  StreamReader sr = new StreamReader("missing.txt");
}
catch {
  Console.WriteLine("File not found");
}

```

## 捕捉块

由于前面的`catch`块没有被设置为处理任何特定的异常，它将捕获所有的异常。这相当于捕获了`System.Exception`类，因为所有的异常都源自这个类。

```cs
catch (Exception) {}

```

为了捕捉更具体的异常，需要将那个`catch`块放在更一般的异常之前。

```cs
catch (FileNotFoundException) {}
catch (Exception) {}

```

`catch`块可以有选择地定义一个异常对象，该对象可以用来获得关于异常的更多信息，比如错误的描述。

```cs
catch (Exception e) {
  Console.WriteLine("Error: " + e.Message);
}

```

## 异常过滤器

C# 6 中增加了异常过滤器，允许`catch`块包含条件。使用`when`关键字将条件附加到`catch`块。只有当条件评估为`true`时，匹配的异常才会被捕获，如下例所示:

```cs
try {
  StreamReader sr = new StreamReader("missing.txt");
}
catch (FileNotFoundException e)
when (e.FileName.Contains(".txt")) {
  Console.WriteLine("Missing file: " + e.FileName);
}

```

使用异常过滤器时，相同的异常类型可能出现在多个`catch`子句中。此外，在某些情况下，更一般的异常可以放在更具体的异常之前。在下一个示例中，通过调用日志记录方法作为异常筛选器来记录所有异常。因为该方法返回`false`，所以一般的异常不会被捕获，从而允许另一个`catch`块处理该异常。

```cs
using System;
using System.IO;

static class ErrorHandling
{
  // Extension method
  public static bool LogException(this Exception e)
  {
    Console.Error.WriteLine($"Exception: {e}");
    return false;
  }

  static void Main()
  {
    try {
      var sr = new StreamReader("missing.txt");
    }
    catch (Exception e) when (LogException(e)) {
      // Never reached
    }
    catch (FileNotFoundException) {
      // Actual handling of exception
    }
  }
}

```

## 最终阻止

作为`try-catch`语句的最后一个子句，可以添加一个`finally`块。该块用于清理在`try`块中分配的某些资源。通常，一旦不再需要有限的系统资源和图形组件，就需要以这种方式释放它们。无论是否有异常，`finally`块中的代码将一直执行。即使`try`块以跳转语句结束，比如`return`，情况也是如此。

在前面使用的例子中，如果在`try`块中打开的文件被成功打开，那么它应该被关闭。这将在下一个代码段中正确完成。为了能够从`finally`子句访问`StreamReader`对象，必须在`try`块之外声明它。请记住，如果您忘记关闭流，垃圾收集器最终会为您关闭它，但最好自己动手。

```cs
StreamReader sr = null;
try {
  sr = new StreamReader("missing.txt");
}
catch (FileNotFoundException) {}
finally {
  if (sr != null) sr.Close();
}

```

前面的语句称为`try-catch-finally`语句。也可以省去`catch`块来创建一个`try-finally`语句。该语句不会捕捉任何异常。相反，它将确保正确处置在`try`块中分配的任何资源。如果分配的资源不抛出任何异常，这可能是有用的。例如，这样一个类在`System.Drawing`名称空间中将是`Bitmap`。

```cs
using System.Drawing;
// ...
Bitmap b = null;
try {
  b = new Bitmap(100, 50);
  System.Console.WriteLine(b.Width); // "100"
}
finally {
  if (b != null) b.Dispose();
}

```

注意，当使用控制台项目时，需要手动添加对`System.Drawing`程序集的引用，以便可以访问这些成员。为此，请在“解决方案资源管理器”窗口中右击“引用”文件夹，然后选择“添加引用”。然后从“程序集➤框架”中，选择`System.Drawing`程序集，并单击“确定”将其引用添加到您的项目中。

## using 语句

`using`语句为编写`try-finally`语句提供了更简单的语法。该语句以`using`关键字开始，后面是括号中指定的要获取的资源。然后，它包含一个代码块，其中可以使用所获得的资源。当代码块执行完毕，自动调用对象的`Dispose`方法进行清理。这个方法来自于`System.IDisposable`接口，所以指定的资源必须实现这个接口。以下代码执行与上一示例相同的功能，但代码行更少:

```cs
using System.Drawing;
// ...
using (Bitmap b = new Bitmap(100, 50)) {
  System.Console.WriteLine(b.Width); // "100"
} // disposed

```

C# 8 通过允许使用声明进一步简化了资源管理。这消除了对花括号的需要，因为当资源处理程序超出范围时，它将被自动处理掉。

```cs
void MyBitmap()
{
  using Bitmap b = new Bitmap(100, 50);
  System.Console.WriteLine(b.Height); // "50"
} // disposed

```

## 抛出异常

当出现方法无法恢复的情况时，它可以生成一个异常，通知调用方该方法已失败。这是通过使用关键字`throw`后跟一个从`System.Exception`派生的类的新实例来完成的。

```cs
static void MakeError()
{
  throw new System.DivideByZeroException("My Error");
}

```

然后，异常将沿调用方堆栈向上传播，直到被捕获。如果调用者捕捉到异常，但无法从中恢复，那么可以只使用`throw`关键字来重新抛出异常。如果没有更多的`try-catch`语句，程序将停止执行并显示错误信息。

```cs
static void Main()
{
  try {
    MakeError();
  }
  catch {
    throw; // rethrow error
  }
}

```

作为一个语句，`throw`关键字不能在需要表达式的上下文中使用，例如在三元语句中。C# 7.0 改变了这一点，允许将`throw`也用作表达式。这扩展了可能引发异常的位置，例如在以下空合并表达式中:

```cs
using System;
class MyClass
{
  private string _name;
  public string name
  {
    get => _name;
    set => _name = value ?? throw new
      ArgumentNullException(nameof(name)+" was null");
  }

  static void Main()
  {
    MyClass c = new MyClass();
    c.name = null; // exception: name was null
  }
}

```

注意这里使用的`nameof`表达式，它是在 C# 6 中引入的。该表达式将括号内的符号转换为字符串。如果重命名属性，这样做的好处就会显现出来，因为 IDE 可以找到并重命名该符号。如果使用了字符串，情况就不是这样了。